Workbook

Sheet Supuestos
A1: Plan de implementación — cafe-gestion (borrador)
A3: Parámetro | B3: Valor | C3: Nota
A4: Fecha de D1 | B4: 46323 | C4: Hoy (mié 28/10/2026). Editable: todo el calendario se recalcula.
A5: Horas netas por día de trabajo | B5: 4 | C5: Supuesto del plan: 1 día ≈ 4 h por persona, con asistente de IA y revisión de PR incluida.
A6: Personas | B6: 2 | C6: A = Django/FastAPI · B = Node/Mongo/Socket.IO.
A7: Modalidad de implementación (TP4) | B7: PC local + docker compose | C7: Si se elige cloud, sumar 1.5–2 días.
A8: Alcance | B8: Solo historias Must | C8: Should y Could (HU9–HU14) fuera del plan.
A10: Leyenda: celdas con fondo amarillo y texto azul = datos editables. Sábados cuentan como día de trabajo; domingos libres.
A11: Los desvíos reales se registran en Plan (columnas Estado, Inicio real, Fin real) para la sección 3 del informe.

Sheet Plan
A1: Plan por tareas — duración en días de trabajo (1 día ≈ 4 h netas)
A3: Fase | B3: ID | C3: Tarea | D3: Detalle | E3: Días A | F3: Días B | G3: Resp. | H3: Ini (D) | I3: Fin (D) | J3: Fecha inicio | K3: Fecha fin | L3: Estado | M3: Inicio real | N3: Fin real | O3: 1 | P3: 2 | Q3: 3 | R3: 4 | S3: 5 | T3: 6 | U3: 7 | V3: 8 | W3: 9 | X3: 10 | Y3: 11 | Z3: 12 | AA3: 13 | AB3: 14 | AC3: 15 | AD3: 16 | AE3: 17 | AF3: 18 | AG3: 19 | AH3: 20 | AI3: 21 | AJ3: 22 | AK3: 23 | AL3: 24 | AM3: 25 | AN3: 26 | AO3: 27 | AP3: 28 | AQ3: 29 | AR3: 30
A4: F0 Cierre TP0 | B4: T0.4v | C4: Verificar/mergear T0.4 y .env no versionado | D4: Clon limpio por el otro integrante | E4: 0.5 | F4: 0.5 | G4: A+B | H4: 1 | I4: 1 | J4: =INDEX(Calendario!$B$2:$B$31,MATCH(H4,Calendario!$A$2:$A$31,0)) -> 46323 | K4: =INDEX(Calendario!$B$2:$B$31,MATCH(I4,Calendario!$A$2:$A$31,0)) -> 46323 | L4: Pendiente | O4: =IF(AND(O$3>=$H4,O$3<=$I4),1,"") -> 1 | P4: =IF(AND(P$3>=$H4,P$3<=$I4),1,"") | Q4: =IF(AND(Q$3>=$H4,Q$3<=$I4),1,"") | R4: =IF(AND(R$3>=$H4,R$3<=$I4),1,"") | S4: =IF(AND(S$3>=$H4,S$3<=$I4),1,"") | T4: =IF(AND(T$3>=$H4,T$3<=$I4),1,"") | U4: =IF(AND(U$3>=$H4,U$3<=$I4),1,"") | V4: =IF(AND(V$3>=$H4,V$3<=$I4),1,"") | ... AR4: =IF(AND(AR$3>=$H4,AR$3<=$I4),1,"")
A5: F0 Cierre TP0 | B5: T0.5 | C5: git-flow, plantilla PR, tablero, protección de main | E5: 0.5 | F5: 0 | G5: A | H5: 1 | I5: 1 | J5: =INDEX(Calendario!$B$2:$B$31,MATCH(H5,Calendario!$A$2:$A$31,0)) -> 46323 | K5: =INDEX(Calendario!$B$2:$B$31,MATCH(I5,Calendario!$A$2:$A$31,0)) -> 46323 | L5: Pendiente | O5: =IF(AND(O$3>=$H5,O$3<=$I5),1,"") -> 1 | P5: =IF(AND(P$3>=$H5,P$3<=$I5),1,"") | Q5: =IF(AND(Q$3>=$H5,Q$3<=$I5),1,"") | R5: =IF(AND(R$3>=$H5,R$3<=$I5),1,"") | S5: =IF(AND(S$3>=$H5,S$3<=$I5),1,"") | T5: =IF(AND(T$3>=$H5,T$3<=$I5),1,"") | U5: =IF(AND(U$3>=$H5,U$3<=$I5),1,"") | V5: =IF(AND(V$3>=$H5,V$3<=$I5),1,"") | ... AR5: =IF(AND(AR$3>=$H5,AR$3<=$I5),1,"")
A6: F0 Cierre TP0 | B6: T0.6 | C6: excel-analisis.md + seed anonimizado | E6: 0 | F6: 0.5 | G6: B | H6: 1 | I6: 2 | J6: =INDEX(Calendario!$B$2:$B$31,MATCH(H6,Calendario!$A$2:$A$31,0)) -> 46323 | K6: =INDEX(Calendario!$B$2:$B$31,MATCH(I6,Calendario!$A$2:$A$31,0)) -> 46324 | L6: Pendiente | O6: =IF(AND(O$3>=$H6,O$3<=$I6),1,"") -> 1 | P6: =IF(AND(P$3>=$H6,P$3<=$I6),1,"") -> 1 | Q6: =IF(AND(Q$3>=$H6,Q$3<=$I6),1,"") | R6: =IF(AND(R$3>=$H6,R$3<=$I6),1,"") | S6: =IF(AND(S$3>=$H6,S$3<=$I6),1,"") | T6: =IF(AND(T$3>=$H6,T$3<=$I6),1,"") | U6: =IF(AND(U$3>=$H6,U$3<=$I6),1,"") | V6: =IF(AND(V$3>=$H6,V$3<=$I6),1,"") | ... AR6: =IF(AND(AR$3>=$H6,AR$3<=$I6),1,"")
A7: F0 Cierre TP0 | B7: T0.7 | C7: Ajustes de docs pendientes | D7: HU15, post-commit/outbox, IVA 27 %, atomicidad stock/caja, QR = URL | E7: 0.5 | F7: 0 | G7: A | H7: 2 | I7: 2 | J7: =INDEX(Calendario!$B$2:$B$31,MATCH(H7,Calendario!$A$2:$A$31,0)) -> 46324 | K7: =INDEX(Calendario!$B$2:$B$31,MATCH(I7,Calendario!$A$2:$A$31,0)) -> 46324 | L7: Pendiente | O7: =IF(AND(O$3>=$H7,O$3<=$I7),1,"") | P7: =IF(AND(P$3>=$H7,P$3<=$I7),1,"") -> 1 | Q7: =IF(AND(Q$3>=$H7,Q$3<=$I7),1,"") | R7: =IF(AND(R$3>=$H7,R$3<=$I7),1,"") | S7: =IF(AND(S$3>=$H7,S$3<=$I7),1,"") | T7: =IF(AND(T$3>=$H7,T$3<=$I7),1,"") | U7: =IF(AND(U$3>=$H7,U$3<=$I7),1,"") | V7: =IF(AND(V$3>=$H7,V$3<=$I7),1,"") | ... AR7: =IF(AND(AR$3>=$H7,AR$3<=$I7),1,"")
A8: F0 Cierre TP0 | B8: T1.0 | C8: docs/api-errores.md (formato único de error) | D8: Exigido por AGENTS.md, aún no existe | E8: 0.5 | F8: 0.5 | G8: A+B | H8: 2 | I8: 2 | J8: =INDEX(Calendario!$B$2:$B$31,MATCH(H8,Calendario!$A$2:$A$31,0)) -> 46324 | K8: =INDEX(Calendario!$B$2:$B$31,MATCH(I8,Calendario!$A$2:$A$31,0)) -> 46324 | L8: Pendiente | O8: =IF(AND(O$3>=$H8,O$3<=$I8),1,"") | P8: =IF(AND(P$3>=$H8,P$3<=$I8),1,"") -> 1 | Q8: =IF(AND(Q$3>=$H8,Q$3<=$I8),1,"") | R8: =IF(AND(R$3>=$H8,R$3<=$I8),1,"") | S8: =IF(AND(S$3>=$H8,S$3<=$I8),1,"") | T8: =IF(AND(T$3>=$H8,T$3<=$I8),1,"") | U8: =IF(AND(U$3>=$H8,U$3<=$I8),1,"") | V8: =IF(AND(V$3>=$H8,V$3<=$I8),1,"") | ... AR8: =IF(AND(AR$3>=$H8,AR$3<=$I8),1,"")
A9: F1 TP1 | B9: T1.9 | C9: Mongo: historial_precios y snapshots_costeo | D9: Esquemas, índices, capas | E9: 0 | F9: 1 | G9: B | H9: 2 | I9: 3 | J9: =INDEX(Calendario!$B$2:$B$31,MATCH(H9,Calendario!$A$2:$A$31,0)) -> 46324 | K9: =INDEX(Calendario!$B$2:$B$31,MATCH(I9,Calendario!$A$2:$A$31,0)) -> 46325 | L9: Pendiente | O9: =IF(AND(O$3>=$H9,O$3<=$I9),1,"") | P9: =IF(AND(P$3>=$H9,P$3<=$I9),1,"") -> 1 | Q9: =IF(AND(Q$3>=$H9,Q$3<=$I9),1,"") -> 1 | R9: =IF(AND(R$3>=$H9,R$3<=$I9),1,"") | S9: =IF(AND(S$3>=$H9,S$3<=$I9),1,"") | T9: =IF(AND(T$3>=$H9,T$3<=$I9),1,"") | U9: =IF(AND(U$3>=$H9,U$3<=$I9),1,"") | V9: =IF(AND(V$3>=$H9,V$3<=$I9),1,"") | ... AR9: =IF(AND(AR$3>=$H9,AR$3<=$I9),1,"")
A10: F1 TP1 | B10: T1.1 | C10: Modelos Proveedor, Insumo, Compra + migraciones | E10: 0.5 | F10: 0 | G10: A | H10: 3 | I10: 3 | J10: =INDEX(Calendario!$B$2:$B$31,MATCH(H10,Calendario!$A$2:$A$31,0)) -> 46325 | K10: =INDEX(Calendario!$B$2:$B$31,MATCH(I10,Calendario!$A$2:$A$31,0)) -> 46325 | L10: Pendiente | O10: =IF(AND(O$3>=$H10,O$3<=$I10),1,"") | P10: =IF(AND(P$3>=$H10,P$3<=$I10),1,"") | Q10: =IF(AND(Q$3>=$H10,Q$3<=$I10),1,"") -> 1 | R10: =IF(AND(R$3>=$H10,R$3<=$I10),1,"") | S10: =IF(AND(S$3>=$H10,S$3<=$I10),1,"") | T10: =IF(AND(T$3>=$H10,T$3<=$I10),1,"") | U10: =IF(AND(U$3>=$H10,U$3<=$I10),1,"") | V10: =IF(AND(V$3>=$H10,V$3<=$I10),1,"") | ... AR10: =IF(AND(AR$3>=$H10,AR$3<=$I10),1,"")
A11: F1 TP1 | B11: T1.10 | C11: Node: errores, logging, paginación, búsqueda | E11: 0 | F11: 0.5 | G11: B | H11: 3 | I11: 3 | J11: =INDEX(Calendario!$B$2:$B$31,MATCH(H11,Calendario!$A$2:$A$31,0)) -> 46325 | K11: =INDEX(Calendario!$B$2:$B$31,MATCH(I11,Calendario!$A$2:$A$31,0)) -> 46325 | L11: Pendiente | O11: =IF(AND(O$3>=$H11,O$3<=$I11),1,"") | P11: =IF(AND(P$3>=$H11,P$3<=$I11),1,"") | Q11: =IF(AND(Q$3>=$H11,Q$3<=$I11),1,"") -> 1 | R11: =IF(AND(R$3>=$H11,R$3<=$I11),1,"") | S11: =IF(AND(S$3>=$H11,S$3<=$I11),1,"") | T11: =IF(AND(T$3>=$H11,T$3<=$I11),1,"") | U11: =IF(AND(U$3>=$H11,U$3<=$I11),1,"") | V11: =IF(AND(V$3>=$H11,V$3<=$I11),1,"") | ... AR11: =IF(AND(AR$3>=$H11,AR$3<=$I11),1,"")
A12: F1 TP1 | B12: T1.2 | C12: Conversión de unidades y costo unitario con prorrateo de envío | D12: Tests con casos del Excel | E12: 1 | F12: 0 | G12: A | H12: 3 | I12: 4 | J12: =INDEX(Calendario!$B$2:$B$31,MATCH(H12,Calendario!$A$2:$A$31,0)) -> 46325 | K12: =INDEX(Calendario!$B$2:$B$31,MATCH(I12,Calendario!$A$2:$A$31,0)) -> 46326 | L12: Pendiente | O12: =IF(AND(O$3>=$H12,O$3<=$I12),1,"") | P12: =IF(AND(P$3>=$H12,P$3<=$I12),1,"") | Q12: =IF(AND(Q$3>=$H12,Q$3<=$I12),1,"") -> 1 | R12: =IF(AND(R$3>=$H12,R$3<=$I12),1,"") -> 1 | S12: =IF(AND(S$3>=$H12,S$3<=$I12),1,"") | T12: =IF(AND(T$3>=$H12,T$3<=$I12),1,"") | U12: =IF(AND(U$3>=$H12,U$3<=$I12),1,"") | V12: =IF(AND(V$3>=$H12,V$3<=$I12),1,"") | ... AR12: =IF(AND(AR$3>=$H12,AR$3<=$I12),1,"")
A13: F1 TP1 | B13: T4.3a | C13: CI base (adelantada) | D13: Instalación, lint y tests | E13: 0 | F13: 0.5 | G13: B | H13: 4 | I13: 4 | J13: =INDEX(Calendario!$B$2:$B$31,MATCH(H13,Calendario!$A$2:$A$31,0)) -> 46326 | K13: =INDEX(Calendario!$B$2:$B$31,MATCH(I13,Calendario!$A$2:$A$31,0)) -> 46326 | L13: Pendiente | O13: =IF(AND(O$3>=$H13,O$3<=$I13),1,"") | P13: =IF(AND(P$3>=$H13,P$3<=$I13),1,"") | Q13: =IF(AND(Q$3>=$H13,Q$3<=$I13),1,"") | R13: =IF(AND(R$3>=$H13,R$3<=$I13),1,"") -> 1 | S13: =IF(AND(S$3>=$H13,S$3<=$I13),1,"") | T13: =IF(AND(T$3>=$H13,T$3<=$I13),1,"") | U13: =IF(AND(U$3>=$H13,U$3<=$I13),1,"") | V13: =IF(AND(V$3>=$H13,V$3<=$I13),1,"") | ... AR13: =IF(AND(AR$3>=$H13,AR$3<=$I13),1,"")
A14: F1 TP1 | B14: T1.3 | C14: Producto, RecetaItem y servicio de costeo | E14: 1 | F14: 0 | G14: A | H14: 4 | I14: 6 | J14: =INDEX(Calendario!$B$2:$B$31,MATCH(H14,Calendario!$A$2:$A$31,0)) -> 46326 | K14: =INDEX(Calendario!$B$2:$B$31,MATCH(I14,Calendario!$A$2:$A$31,0)) -> 46328 | L14: Pendiente | O14: =IF(AND(O$3>=$H14,O$3<=$I14),1,"") | P14: =IF(AND(P$3>=$H14,P$3<=$I14),1,"") | Q14: =IF(AND(Q$3>=$H14,Q$3<=$I14),1,"") | R14: =IF(AND(R$3>=$H14,R$3<=$I14),1,"") -> 1 | S14: =IF(AND(S$3>=$H14,S$3<=$I14),1,"") -> 1 | T14: =IF(AND(T$3>=$H14,T$3<=$I14),1,"") -> 1 | U14: =IF(AND(U$3>=$H14,U$3<=$I14),1,"") | V14: =IF(AND(V$3>=$H14,V$3<=$I14),1,"") | ... AR14: =IF(AND(AR$3>=$H14,AR$3<=$I14),1,"")
A15: F1 TP1 | B15: T1.6b | C15: TurnoCaja y MovimientoCaja con endpoints | E15: 0 | F15: 1 | G15: B | H15: 4 | I15: 6 | J15: =INDEX(Calendario!$B$2:$B$31,MATCH(H15,Calendario!$A$2:$A$31,0)) -> 46326 | K15: =INDEX(Calendario!$B$2:$B$31,MATCH(I15,Calendario!$A$2:$A$31,0)) -> 46328 | L15: Pendiente | O15: =IF(AND(O$3>=$H15,O$3<=$I15),1,"") | P15: =IF(AND(P$3>=$H15,P$3<=$I15),1,"") | Q15: =IF(AND(Q$3>=$H15,Q$3<=$I15),1,"") | R15: =IF(AND(R$3>=$H15,R$3<=$I15),1,"") -> 1 | S15: =IF(AND(S$3>=$H15,S$3<=$I15),1,"") -> 1 | T15: =IF(AND(T$3>=$H15,T$3<=$I15),1,"") -> 1 | U15: =IF(AND(U$3>=$H15,U$3<=$I15),1,"") | V15: =IF(AND(V$3>=$H15,V$3<=$I15),1,"") | ... AR15: =IF(AND(AR$3>=$H15,AR$3<=$I15),1,"")
A16: F1 TP1 | B16: T1.8 | C16: Recalcular recetas al guardar una compra | E16: 0.5 | F16: 0 | G16: A | H16: 6 | I16: 6 | J16: =INDEX(Calendario!$B$2:$B$31,MATCH(H16,Calendario!$A$2:$A$31,0)) -> 46328 | K16: =INDEX(Calendario!$B$2:$B$31,MATCH(I16,Calendario!$A$2:$A$31,0)) -> 46328 | L16: Pendiente | O16: =IF(AND(O$3>=$H16,O$3<=$I16),1,"") | P16: =IF(AND(P$3>=$H16,P$3<=$I16),1,"") | Q16: =IF(AND(Q$3>=$H16,Q$3<=$I16),1,"") | R16: =IF(AND(R$3>=$H16,R$3<=$I16),1,"") | S16: =IF(AND(S$3>=$H16,S$3<=$I16),1,"") | T16: =IF(AND(T$3>=$H16,T$3<=$I16),1,"") -> 1 | U16: =IF(AND(U$3>=$H16,U$3<=$I16),1,"") | V16: =IF(AND(V$3>=$H16,V$3<=$I16),1,"") | ... AR16: =IF(AND(AR$3>=$H16,AR$3<=$I16),1,"")
A17: F1 TP1 | B17: T1.7 | C17: Comando seed_demo | E17: 0 | F17: 0.5 | G17: B | H17: 6 | I17: 6 | J17: =INDEX(Calendario!$B$2:$B$31,MATCH(H17,Calendario!$A$2:$A$31,0)) -> 46328 | K17: =INDEX(Calendario!$B$2:$B$31,MATCH(I17,Calendario!$A$2:$A$31,0)) -> 46328 | L17: Pendiente | O17: =IF(AND(O$3>=$H17,O$3<=$I17),1,"") | P17: =IF(AND(P$3>=$H17,P$3<=$I17),1,"") | Q17: =IF(AND(Q$3>=$H17,Q$3<=$I17),1,"") | R17: =IF(AND(R$3>=$H17,R$3<=$I17),1,"") | S17: =IF(AND(S$3>=$H17,S$3<=$I17),1,"") | T17: =IF(AND(T$3>=$H17,T$3<=$I17),1,"") -> 1 | U17: =IF(AND(U$3>=$H17,U$3<=$I17),1,"") | V17: =IF(AND(V$3>=$H17,V$3<=$I17),1,"") | ... AR17: =IF(AND(AR$3>=$H17,AR$3<=$I17),1,"")
A18: F1 TP1 | B18: T1.4 | C18: ViewSets, paginación, 3 filtros, validaciones | E18: 1 | F18: 0 | G18: A | H18: 7 | I18: 7 | J18: =INDEX(Calendario!$B$2:$B$31,MATCH(H18,Calendario!$A$2:$A$31,0)) -> 46329 | K18: =INDEX(Calendario!$B$2:$B$31,MATCH(I18,Calendario!$A$2:$A$31,0)) -> 46329 | L18: Pendiente | O18: =IF(AND(O$3>=$H18,O$3<=$I18),1,"") | P18: =IF(AND(P$3>=$H18,P$3<=$I18),1,"") | Q18: =IF(AND(Q$3>=$H18,Q$3<=$I18),1,"") | R18: =IF(AND(R$3>=$H18,R$3<=$I18),1,"") | S18: =IF(AND(S$3>=$H18,S$3<=$I18),1,"") | T18: =IF(AND(T$3>=$H18,T$3<=$I18),1,"") | U18: =IF(AND(U$3>=$H18,U$3<=$I18),1,"") -> 1 | V18: =IF(AND(V$3>=$H18,V$3<=$I18),1,"") | ... AR18: =IF(AND(AR$3>=$H18,AR$3<=$I18),1,"")
A19: F1 TP1 | B19: T1.11 | C19: Node consume Django (timeout, degradado) + integracion.md | E19: 0 | F19: 0.5 | G19: B | H19: 7 | I19: 7 | J19: =INDEX(Calendario!$B$2:$B$31,MATCH(H19,Calendario!$A$2:$A$31,0)) -> 46329 | K19: =INDEX(Calendario!$B$2:$B$31,MATCH(I19,Calendario!$A$2:$A$31,0)) -> 46329 | L19: Pendiente | O19: =IF(AND(O$3>=$H19,O$3<=$I19),1,"") | P19: =IF(AND(P$3>=$H19,P$3<=$I19),1,"") | Q19: =IF(AND(Q$3>=$H19,Q$3<=$I19),1,"") | R19: =IF(AND(R$3>=$H19,R$3<=$I19),1,"") | S19: =IF(AND(S$3>=$H19,S$3<=$I19),1,"") | T19: =IF(AND(T$3>=$H19,T$3<=$I19),1,"") | U19: =IF(AND(U$3>=$H19,U$3<=$I19),1,"") -> 1 | V19: =IF(AND(V$3>=$H19,V$3<=$I19),1,"") | ... AR19: =IF(AND(AR$3>=$H19,AR$3<=$I19),1,"")
A20: F1 TP1 | B20: T3.0 | C20: Probar Ollama/Gemini en la PC del equipo | D20: Spike de riesgo | E20: 0 | F20: 0.5 | G20: B | H20: 7 | I20: 7 | J20: =INDEX(Calendario!$B$2:$B$31,MATCH(H20,Calendario!$A$2:$A$31,0)) -> 46329 | K20: =INDEX(Calendario!$B$2:$B$31,MATCH(I20,Calendario!$A$2:$A$31,0)) -> 46329 | L20: Pendiente | O20: =IF(AND(O$3>=$H20,O$3<=$I20),1,"") | P20: =IF(AND(P$3>=$H20,P$3<=$I20),1,"") | Q20: =IF(AND(Q$3>=$H20,Q$3<=$I20),1,"") | R20: =IF(AND(R$3>=$H20,R$3<=$I20),1,"") | S20: =IF(AND(S$3>=$H20,S$3<=$I20),1,"") | T20: =IF(AND(T$3>=$H20,T$3<=$I20),1,"") | U20: =IF(AND(U$3>=$H20,U$3<=$I20),1,"") -> 1 | V20: =IF(AND(V$3>=$H20,V$3<=$I20),1,"") | ... AR20: =IF(AND(AR$3>=$H20,AR$3<=$I20),1,"")
A21: F1 TP1 | B21: T1.5 | C21: Exception handler propio | E21: 0.5 | F21: 0 | G21: A | H21: 8 | I21: 8 | J21: =INDEX(Calendario!$B$2:$B$31,MATCH(H21,Calendario!$A$2:$A$31,0)) -> 46330 | K21: =INDEX(Calendario!$B$2:$B$31,MATCH(I21,Calendario!$A$2:$A$31,0)) -> 46330 | L21: Pendiente | O21: =IF(AND(O$3>=$H21,O$3<=$I21),1,"") | P21: =IF(AND(P$3>=$H21,P$3<=$I21),1,"") | Q21: =IF(AND(Q$3>=$H21,Q$3<=$I21),1,"") | R21: =IF(AND(R$3>=$H21,R$3<=$I21),1,"") | S21: =IF(AND(S$3>=$H21,S$3<=$I21),1,"") | T21: =IF(AND(T$3>=$H21,T$3<=$I21),1,"") | U21: =IF(AND(U$3>=$H21,U$3<=$I21),1,"") | V21: =IF(AND(V$3>=$H21,V$3<=$I21),1,"") -> 1 | ... AR21: =IF(AND(AR$3>=$H21,AR$3<=$I21),1,"")
A22: F1 TP1 | B22: T1.6a | C22: Venta y VentaItem con snapshot de costo | E22: 1 | F22: 0 | G22: A | H22: 8 | I22: 9 | J22: =INDEX(Calendario!$B$2:$B$31,MATCH(H22,Calendario!$A$2:$A$31,0)) -> 46330 | K22: =INDEX(Calendario!$B$2:$B$31,MATCH(I22,Calendario!$A$2:$A$31,0)) -> 46331 | L22: Pendiente | O22: =IF(AND(O$3>=$H22,O$3<=$I22),1,"") | P22: =IF(AND(P$3>=$H22,P$3<=$I22),1,"") | Q22: =IF(AND(Q$3>=$H22,Q$3<=$I22),1,"") | R22: =IF(AND(R$3>=$H22,R$3<=$I22),1,"") | S22: =IF(AND(S$3>=$H22,S$3<=$I22),1,"") | T22: =IF(AND(T$3>=$H22,T$3<=$I22),1,"") | U22: =IF(AND(U$3>=$H22,U$3<=$I22),1,"") | V22: =IF(AND(V$3>=$H22,V$3<=$I22),1,"") -> 1 | ... AR22: =IF(AND(AR$3>=$H22,AR$3<=$I22),1,"")
A23: F1 TP1 | B23: T1.12 | C23: Colección de peticiones + 4 tests por servicio | E23: 0 | F23: 0.5 | G23: B | H23: 8 | I23: 8 | J23: =INDEX(Calendario!$B$2:$B$31,MATCH(H23,Calendario!$A$2:$A$31,0)) -> 46330 | K23: =INDEX(Calendario!$B$2:$B$31,MATCH(I23,Calendario!$A$2:$A$31,0)) -> 46330 | L23: Pendiente | O23: =IF(AND(O$3>=$H23,O$3<=$I23),1,"") | P23: =IF(AND(P$3>=$H23,P$3<=$I23),1,"") | Q23: =IF(AND(Q$3>=$H23,Q$3<=$I23),1,"") | R23: =IF(AND(R$3>=$H23,R$3<=$I23),1,"") | S23: =IF(AND(S$3>=$H23,S$3<=$I23),1,"") | T23: =IF(AND(T$3>=$H23,T$3<=$I23),1,"") | U23: =IF(AND(U$3>=$H23,U$3<=$I23),1,"") | V23: =IF(AND(V$3>=$H23,V$3<=$I23),1,"") -> 1 | ... AR23: =IF(AND(AR$3>=$H23,AR$3<=$I23),1,"")
A24: F1 TP1 | B24: T1.13 | C24: Verificación en clon limpio | E24: 0.5 | F24: 0.5 | G24: A+B | H24: 9 | I24: 9 | J24: =INDEX(Calendario!$B$2:$B$31,MATCH(H24,Calendario!$A$2:$A$31,0)) -> 46331 | K24: =INDEX(Calendario!$B$2:$B$31,MATCH(I24,Calendario!$A$2:$A$31,0)) -> 46331 | L24: Pendiente | O24: =IF(AND(O$3>=$H24,O$3<=$I24),1,"") | P24: =IF(AND(P$3>=$H24,P$3<=$I24),1,"") | Q24: =IF(AND(Q$3>=$H24,Q$3<=$I24),1,"") | R24: =IF(AND(R$3>=$H24,R$3<=$I24),1,"") | S24: =IF(AND(S$3>=$H24,S$3<=$I24),1,"") | T24: =IF(AND(T$3>=$H24,T$3<=$I24),1,"") | U24: =IF(AND(U$3>=$H24,U$3<=$I24),1,"") | V24: =IF(AND(V$3>=$H24,V$3<=$I24),1,"") | ... AR24: =IF(AND(AR$3>=$H24,AR$3<=$I24),1,"")
A25: F2 TP2 | B25: T2.1 | C25: seguridad.md (matriz de roles) + ADR JWT RS256 | D25: Antes de codificar | E25: 0.5 | F25: 0.5 | G25: A+B | H25: 10 | I25: 10 | J25: =INDEX(Calendario!$B$2:$B$31,MATCH(H25,Calendario!$A$2:$A$31,0)) -> 46332 | K25: =INDEX(Calendario!$B$2:$B$31,MATCH(I25,Calendario!$A$2:$A$31,0)) -> 46332 | L25: Pendiente | O25: =IF(AND(O$3>=$H25,O$3<=$I25),1,"") | P25: =IF(AND(P$3>=$H25,P$3<=$I25),1,"") | Q25: =IF(AND(Q$3>=$H25,Q$3<=$I25),1,"") | R25: =IF(AND(R$3>=$H25,R$3<=$I25),1,"") | S25: =IF(AND(S$3>=$H25,S$3<=$I25),1,"") | T25: =IF(AND(T$3>=$H25,T$3<=$I25),1,"") | U25: =IF(AND(U$3>=$H25,U$3<=$I25),1,"") | V25: =IF(AND(V$3>=$H25,V$3<=$I25),1,"") | ... AR25: =IF(AND(AR$3>=$H25,AR$3<=$I25),1,"")
A26: F2 TP2 | B26: T2.2 | C26: SimpleJWT: login, refresh, blacklist | E26: 1 | F26: 0 | G26: A | H26: 10 | I26: 11 | J26: =INDEX(Calendario!$B$2:$B$31,MATCH(H26,Calendario!$A$2:$A$31,0)) -> 46332 | K26: =INDEX(Calendario!$B$2:$B$31,MATCH(I26,Calendario!$A$2:$A$31,0)) -> 46333 | L26: Pendiente | O26: =IF(AND(O$3>=$H26,O$3<=$I26),1,"") | P26: =IF(AND(P$3>=$H26,P$3<=$I26),1,"") | Q26: =IF(AND(Q$3>=$H26,Q$3<=$I26),1,"") | R26: =IF(AND(R$3>=$H26,R$3<=$I26),1,"") | S26: =IF(AND(S$3>=$H26,S$3<=$I26),1,"") | T26: =IF(AND(T$3>=$H26,T$3<=$I26),1,"") | U26: =IF(AND(U$3>=$H26,U$3<=$I26),1,"") | V26: =IF(AND(V$3>=$H26,V$3<=$I26),1,"") | ... AR26: =IF(AND(AR$3>=$H26,AR$3<=$I26),1,"")
A27: F2 TP2 | B27: T2.4 | C27: Node valida JWT y autoriza por rol | E27: 0 | F27: 1 | G27: B | H27: 10 | I27: 11 | J27: =INDEX(Calendario!$B$2:$B$31,MATCH(H27,Calendario!$A$2:$A$31,0)) -> 46332 | K27: =INDEX(Calendario!$B$2:$B$31,MATCH(I27,Calendario!$A$2:$A$31,0)) -> 46333 | L27: Pendiente | O27: =IF(AND(O$3>=$H27,O$3<=$I27),1,"") | P27: =IF(AND(P$3>=$H27,P$3<=$I27),1,"") | Q27: =IF(AND(Q$3>=$H27,Q$3<=$I27),1,"") | R27: =IF(AND(R$3>=$H27,R$3<=$I27),1,"") | S27: =IF(AND(S$3>=$H27,S$3<=$I27),1,"") | T27: =IF(AND(T$3>=$H27,T$3<=$I27),1,"") | U27: =IF(AND(U$3>=$H27,U$3<=$I27),1,"") | V27: =IF(AND(V$3>=$H27,V$3<=$I27),1,"") | ... AR27: =IF(AND(AR$3>=$H27,AR$3<=$I27),1,"")
A28: F2 TP2 | B28: T2.3 | C28: Roles plantilla, permisos, CRUD personal, permisos por objeto | E28: 1.5 | F28: 0 | G28: A | H28: 11 | I28: 13 | J28: =INDEX(Calendario!$B$2:$B$31,MATCH(H28,Calendario!$A$2:$A$31,0)) -> 46333 | K28: =INDEX(Calendario!$B$2:$B$31,MATCH(I28,Calendario!$A$2:$A$31,0)) -> 46335 | L28: Pendiente | O28: =IF(AND(O$3>=$H28,O$3<=$I28),1,"") | P28: =IF(AND(P$3>=$H28,P$3<=$I28),1,"") | Q28: =IF(AND(Q$3>=$H28,Q$3<=$I28),1,"") | R28: =IF(AND(R$3>=$H28,R$3<=$I28),1,"") | S28: =IF(AND(S$3>=$H28,S$3<=$I28),1,"") | T28: =IF(AND(T$3>=$H28,T$3<=$I28),1,"") | U28: =IF(AND(U$3>=$H28,U$3<=$I28),1,"") | V28: =IF(AND(V$3>=$H28,V$3<=$I28),1,"") | ... AR28: =IF(AND(AR$3>=$H28,AR$3<=$I28),1,"")
A29: F2 TP2 | B29: T2.5b | C29: Node: CORS, rate limit, helmet, validación, sanitización NoSQL | E29: 0 | F29: 1.5 | G29: B | H29: 11 | I29: 13 | J29: =INDEX(Calendario!$B$2:$B$31,MATCH(H29,Calendario!$A$2:$A$31,0)) -> 46333 | K29: =INDEX(Calendario!$B$2:$B$31,MATCH(I29,Calendario!$A$2:$A$31,0)) -> 46335 | L29: Pendiente | O29: =IF(AND(O$3>=$H29,O$3<=$I29),1,"") | P29: =IF(AND(P$3>=$H29,P$3<=$I29),1,"") | Q29: =IF(AND(Q$3>=$H29,Q$3<=$I29),1,"") | R29: =IF(AND(R$3>=$H29,R$3<=$I29),1,"") | S29: =IF(AND(S$3>=$H29,S$3<=$I29),1,"") | T29: =IF(AND(T$3>=$H29,T$3<=$I29),1,"") | U29: =IF(AND(U$3>=$H29,U$3<=$I29),1,"") | V29: =IF(AND(V$3>=$H29,V$3<=$I29),1,"") | ... AR29: =IF(AND(AR$3>=$H29,AR$3<=$I29),1,"")
A30: F2 TP2 | B30: T2.5a | C30: Django: CORS y throttling | E30: 0.5 | F30: 0 | G30: A | H30: 14 | I30: 14 | J30: =INDEX(Calendario!$B$2:$B$31,MATCH(H30,Calendario!$A$2:$A$31,0)) -> 46336 | K30: =INDEX(Calendario!$B$2:$B$31,MATCH(I30,Calendario!$A$2:$A$31,0)) -> 46336 | L30: Pendiente | O30: =IF(AND(O$3>=$H30,O$3<=$I30),1,"") | P30: =IF(AND(P$3>=$H30,P$3<=$I30),1,"") | Q30: =IF(AND(Q$3>=$H30,Q$3<=$I30),1,"") | R30: =IF(AND(R$3>=$H30,R$3<=$I30),1,"") | S30: =IF(AND(S$3>=$H30,S$3<=$I30),1,"") | T30: =IF(AND(T$3>=$H30,T$3<=$I30),1,"") | U30: =IF(AND(U$3>=$H30,U$3<=$I30),1,"") | V30: =IF(AND(V$3>=$H30,V$3<=$I30),1,"") | ... AR30: =IF(AND(AR$3>=$H30,AR$3<=$I30),1,"")
A31: F2 TP2 | B31: T2.6 | C31: Un test negativo por permiso | D31: A: Django 1.0 · B: Node 0.5 | E31: 1 | F31: 0.5 | G31: A+B | H31: 14 | I31: 15 | J31: =INDEX(Calendario!$B$2:$B$31,MATCH(H31,Calendario!$A$2:$A$31,0)) -> 46336 | K31: =INDEX(Calendario!$B$2:$B$31,MATCH(I31,Calendario!$A$2:$A$31,0)) -> 46337 | L31: Pendiente | O31: =IF(AND(O$3>=$H31,O$3<=$I31),1,"") | P31: =IF(AND(P$3>=$H31,P$3<=$I31),1,"") | Q31: =IF(AND(Q$3>=$H31,Q$3<=$I31),1,"") | R31: =IF(AND(R$3>=$H31,R$3<=$I31),1,"") | S31: =IF(AND(S$3>=$H31,S$3<=$I31),1,"") | T31: =IF(AND(T$3>=$H31,T$3<=$I31),1,"") | U31: =IF(AND(U$3>=$H31,U$3<=$I31),1,"") | V31: =IF(AND(V$3>=$H31,V$3<=$I31),1,"") | ... AR31: =IF(AND(AR$3>=$H31,AR$3<=$I31),1,"")
A32: F2 TP2 | B32: T2.7 | C32: Revisión de secretos e informe de auditoría | E32: 0 | F32: 0.5 | G32: B | H32: 14 | I32: 14 | J32: =INDEX(Calendario!$B$2:$B$31,MATCH(H32,Calendario!$A$2:$A$31,0)) -> 46336 | K32: =INDEX(Calendario!$B$2:$B$31,MATCH(I32,Calendario!$A$2:$A$31,0)) -> 46336 | L32: Pendiente | O32: =IF(AND(O$3>=$H32,O$3<=$I32),1,"") | P32: =IF(AND(P$3>=$H32,P$3<=$I32),1,"") | Q32: =IF(AND(Q$3>=$H32,Q$3<=$I32),1,"") | R32: =IF(AND(R$3>=$H32,R$3<=$I32),1,"") | S32: =IF(AND(S$3>=$H32,S$3<=$I32),1,"") | T32: =IF(AND(T$3>=$H32,T$3<=$I32),1,"") | U32: =IF(AND(U$3>=$H32,U$3<=$I32),1,"") | V32: =IF(AND(V$3>=$H32,V$3<=$I32),1,"") | ... AR32: =IF(AND(AR$3>=$H32,AR$3<=$I32),1,"")
A33: F2 TP2 | B33: T2.8 | C33: Auditoría cruzada en clase | E33: 0.5 | F33: 0.5 | G33: A+B | H33: 16 | I33: 16 | J33: =INDEX(Calendario!$B$2:$B$31,MATCH(H33,Calendario!$A$2:$A$31,0)) -> 46338 | K33: =INDEX(Calendario!$B$2:$B$31,MATCH(I33,Calendario!$A$2:$A$31,0)) -> 46338 | L33: Pendiente | O33: =IF(AND(O$3>=$H33,O$3<=$I33),1,"") | P33: =IF(AND(P$3>=$H33,P$3<=$I33),1,"") | Q33: =IF(AND(Q$3>=$H33,Q$3<=$I33),1,"") | R33: =IF(AND(R$3>=$H33,R$3<=$I33),1,"") | S33: =IF(AND(S$3>=$H33,S$3<=$I33),1,"") | T33: =IF(AND(T$3>=$H33,T$3<=$I33),1,"") | U33: =IF(AND(U$3>=$H33,U$3<=$I33),1,"") | V33: =IF(AND(V$3>=$H33,V$3<=$I33),1,"") | ... AR33: =IF(AND(AR$3>=$H33,AR$3<=$I33),1,"")
A34: F3 TP3 | B34: T3.1 | C34: ai-service: 2 endpoints, prompts v1, Pydantic, contingencia, adapter | E34: 1.5 | F34: 0 | G34: A | H34: 15 | I34: 17 | J34: =INDEX(Calendario!$B$2:$B$31,MATCH(H34,Calendario!$A$2:$A$31,0)) -> 46337 | K34: =INDEX(Calendario!$B$2:$B$31,MATCH(I34,Calendario!$A$2:$A$31,0)) -> 46339 | L34: Pendiente | O34: =IF(AND(O$3>=$H34,O$3<=$I34),1,"") | P34: =IF(AND(P$3>=$H34,P$3<=$I34),1,"") | Q34: =IF(AND(Q$3>=$H34,Q$3<=$I34),1,"") | R34: =IF(AND(R$3>=$H34,R$3<=$I34),1,"") | S34: =IF(AND(S$3>=$H34,S$3<=$I34),1,"") | T34: =IF(AND(T$3>=$H34,T$3<=$I34),1,"") | U34: =IF(AND(U$3>=$H34,U$3<=$I34),1,"") | V34: =IF(AND(V$3>=$H34,V$3<=$I34),1,"") | ... AR34: =IF(AND(AR$3>=$H34,AR$3<=$I34),1,"")
A35: F3 TP3 | B35: T3.5 | C35: Socket.IO: handshake JWT, salas, eventos, presencia, reconexión | E35: 0 | F35: 2 | G35: B | H35: 15 | I35: 17 | J35: =INDEX(Calendario!$B$2:$B$31,MATCH(H35,Calendario!$A$2:$A$31,0)) -> 46337 | K35: =INDEX(Calendario!$B$2:$B$31,MATCH(I35,Calendario!$A$2:$A$31,0)) -> 46339 | L35: Pendiente | O35: =IF(AND(O$3>=$H35,O$3<=$I35),1,"") | P35: =IF(AND(P$3>=$H35,P$3<=$I35),1,"") | Q35: =IF(AND(Q$3>=$H35,Q$3<=$I35),1,"") | R35: =IF(AND(R$3>=$H35,R$3<=$I35),1,"") | S35: =IF(AND(S$3>=$H35,S$3<=$I35),1,"") | T35: =IF(AND(T$3>=$H35,T$3<=$I35),1,"") | U35: =IF(AND(U$3>=$H35,U$3<=$I35),1,"") | V35: =IF(AND(V$3>=$H35,V$3<=$I35),1,"") | ... AR35: =IF(AND(AR$3>=$H35,AR$3<=$I35),1,"")
A36: F3 TP3 | B36: T3.3a | C36: Django: crear compra al aprobar y avisar a Node | E36: 0.5 | F36: 0 | G36: A | H36: 17 | I36: 17 | J36: =INDEX(Calendario!$B$2:$B$31,MATCH(H36,Calendario!$A$2:$A$31,0)) -> 46339 | K36: =INDEX(Calendario!$B$2:$B$31,MATCH(I36,Calendario!$A$2:$A$31,0)) -> 46339 | L36: Pendiente | O36: =IF(AND(O$3>=$H36,O$3<=$I36),1,"") | P36: =IF(AND(P$3>=$H36,P$3<=$I36),1,"") | Q36: =IF(AND(Q$3>=$H36,Q$3<=$I36),1,"") | R36: =IF(AND(R$3>=$H36,R$3<=$I36),1,"") | S36: =IF(AND(S$3>=$H36,S$3<=$I36),1,"") | T36: =IF(AND(T$3>=$H36,T$3<=$I36),1,"") | U36: =IF(AND(U$3>=$H36,U$3<=$I36),1,"") | V36: =IF(AND(V$3>=$H36,V$3<=$I36),1,"") | ... AR36: =IF(AND(AR$3>=$H36,AR$3<=$I36),1,"")
A37: F3 TP3 | B37: T3.2 | C37: Node consume la IA (202 asíncrono) y guarda en Mongo | E37: 0 | F37: 1.5 | G37: B | H37: 17 | I37: 18 | J37: =INDEX(Calendario!$B$2:$B$31,MATCH(H37,Calendario!$A$2:$A$31,0)) -> 46339 | K37: =INDEX(Calendario!$B$2:$B$31,MATCH(I37,Calendario!$A$2:$A$31,0)) -> 46340 | L37: Pendiente | O37: =IF(AND(O$3>=$H37,O$3<=$I37),1,"") | P37: =IF(AND(P$3>=$H37,P$3<=$I37),1,"") | Q37: =IF(AND(Q$3>=$H37,Q$3<=$I37),1,"") | R37: =IF(AND(R$3>=$H37,R$3<=$I37),1,"") | S37: =IF(AND(S$3>=$H37,S$3<=$I37),1,"") | T37: =IF(AND(T$3>=$H37,T$3<=$I37),1,"") | U37: =IF(AND(U$3>=$H37,U$3<=$I37),1,"") | V37: =IF(AND(V$3>=$H37,V$3<=$I37),1,"") | ... AR37: =IF(AND(AR$3>=$H37,AR$3<=$I37),1,"")
A38: F3 TP3 | B38: T3.4 | C38: 3 consultas problemáticas, índices, EXPLAIN antes/después | D38: Incluye seed de 50k ventas | E38: 1 | F38: 0 | G38: A | H38: 18 | I38: 18 | J38: =INDEX(Calendario!$B$2:$B$31,MATCH(H38,Calendario!$A$2:$A$31,0)) -> 46340 | K38: =INDEX(Calendario!$B$2:$B$31,MATCH(I38,Calendario!$A$2:$A$31,0)) -> 46340 | L38: Pendiente | O38: =IF(AND(O$3>=$H38,O$3<=$I38),1,"") | P38: =IF(AND(P$3>=$H38,P$3<=$I38),1,"") | Q38: =IF(AND(Q$3>=$H38,Q$3<=$I38),1,"") | R38: =IF(AND(R$3>=$H38,R$3<=$I38),1,"") | S38: =IF(AND(S$3>=$H38,S$3<=$I38),1,"") | T38: =IF(AND(T$3>=$H38,T$3<=$I38),1,"") | U38: =IF(AND(U$3>=$H38,U$3<=$I38),1,"") | V38: =IF(AND(V$3>=$H38,V$3<=$I38),1,"") | ... AR38: =IF(AND(AR$3>=$H38,AR$3<=$I38),1,"")
A39: F3 TP3 | B39: T3.3b | C39: Node: flujo de aprobación completo | E39: 0 | F39: 1 | G39: B | H39: 20 | I39: 21 | J39: =INDEX(Calendario!$B$2:$B$31,MATCH(H39,Calendario!$A$2:$A$31,0)) -> 46342 | K39: =INDEX(Calendario!$B$2:$B$31,MATCH(I39,Calendario!$A$2:$A$31,0)) -> 46343 | L39: Pendiente | O39: =IF(AND(O$3>=$H39,O$3<=$I39),1,"") | P39: =IF(AND(P$3>=$H39,P$3<=$I39),1,"") | Q39: =IF(AND(Q$3>=$H39,Q$3<=$I39),1,"") | R39: =IF(AND(R$3>=$H39,R$3<=$I39),1,"") | S39: =IF(AND(S$3>=$H39,S$3<=$I39),1,"") | T39: =IF(AND(T$3>=$H39,T$3<=$I39),1,"") | U39: =IF(AND(U$3>=$H39,U$3<=$I39),1,"") | V39: =IF(AND(V$3>=$H39,V$3<=$I39),1,"") | ... AR39: =IF(AND(AR$3>=$H39,AR$3<=$I39),1,"")
A40: F3 TP3 | B40: T3.6 | C40: Cliente mínimo web (B) + diagrama de secuencia (A) | E40: 0.5 | F40: 1 | G40: A+B | H40: 20 | I40: 22 | J40: =INDEX(Calendario!$B$2:$B$31,MATCH(H40,Calendario!$A$2:$A$31,0)) -> 46342 | K40: =INDEX(Calendario!$B$2:$B$31,MATCH(I40,Calendario!$A$2:$A$31,0)) -> 46344 | L40: Pendiente | O40: =IF(AND(O$3>=$H40,O$3<=$I40),1,"") | P40: =IF(AND(P$3>=$H40,P$3<=$I40),1,"") | Q40: =IF(AND(Q$3>=$H40,Q$3<=$I40),1,"") | R40: =IF(AND(R$3>=$H40,R$3<=$I40),1,"") | S40: =IF(AND(S$3>=$H40,S$3<=$I40),1,"") | T40: =IF(AND(T$3>=$H40,T$3<=$I40),1,"") | U40: =IF(AND(U$3>=$H40,U$3<=$I40),1,"") | V40: =IF(AND(V$3>=$H40,V$3<=$I40),1,"") | ... AR40: =IF(AND(AR$3>=$H40,AR$3<=$I40),1,"")
A41: F3 TP3 | B41: T3.7 | C41: Ensayo de fallos | D41: Apagar cada componente y documentar | E41: 0.5 | F41: 0.5 | G41: A+B | H41: 22 | I41: 22 | J41: =INDEX(Calendario!$B$2:$B$31,MATCH(H41,Calendario!$A$2:$A$31,0)) -> 46344 | K41: =INDEX(Calendario!$B$2:$B$31,MATCH(I41,Calendario!$A$2:$A$31,0)) -> 46344 | L41: Pendiente | O41: =IF(AND(O$3>=$H41,O$3<=$I41),1,"") | P41: =IF(AND(P$3>=$H41,P$3<=$I41),1,"") | Q41: =IF(AND(Q$3>=$H41,Q$3<=$I41),1,"") | R41: =IF(AND(R$3>=$H41,R$3<=$I41),1,"") | S41: =IF(AND(S$3>=$H41,S$3<=$I41),1,"") | T41: =IF(AND(T$3>=$H41,T$3<=$I41),1,"") | U41: =IF(AND(U$3>=$H41,U$3<=$I41),1,"") | V41: =IF(AND(V$3>=$H41,V$3<=$I41),1,"") | ... AR41: =IF(AND(AR$3>=$H41,AR$3<=$I41),1,"")
...

Sheet Carga
A1: Carga por fase y persona (días de trabajo)
A3: Fase | B3: Días A | C3: Días B
A4: F0 Cierre TP0 | B4: =SUMIFS(Plan!$E$4:$E$53,Plan!$A$4:$A$53,$A4) -> 2 | C4: =SUMIFS(Plan!$F$4:$F$53,Plan!$A$4:$A$53,$A4) -> 1.5
A5: F1 TP1 | B5: =SUMIFS(Plan!$E$4:$E$53,Plan!$A$4:$A$53,$A5) -> 6 | C5: =SUMIFS(Plan!$F$4:$F$53,Plan!$A$4:$A$53,$A5) -> 5.5
A6: F2 TP2 | B6: =SUMIFS(Plan!$E$4:$E$53,Plan!$A$4:$A$53,$A6) -> 5 | C6: =SUMIFS(Plan!$F$4:$F$53,Plan!$A$4:$A$53,$A6) -> 4.5
A7: F3 TP3 | B7: =SUMIFS(Plan!$E$4:$E$53,Plan!$A$4:$A$53,$A7) -> 4 | C7: =SUMIFS(Plan!$F$4:$F$53,Plan!$A$4:$A$53,$A7) -> 6
A8: F4 TP4 | B8: =SUMIFS(Plan!$E$4:$E$53,Plan!$A$4:$A$53,$A8) -> 3.5 | C8: =SUMIFS(Plan!$F$4:$F$53,Plan!$A$4:$A$53,$A8) -> 3.5
A9: F5 TFI | B9: =SUMIFS(Plan!$E$4:$E$53,Plan!$A$4:$A$53,$A9) -> 3.5 | C9: =SUMIFS(Plan!$F$4:$F$53,Plan!$A$4:$A$53,$A9) -> 3
A10: Total planificado | B10: =SUM(B4:B9) -> 24 | C10: =SUM(C4:C9) -> 24
A11: Capacidad (días laborables) | B11: =COUNTIF(Calendario!$D$2:$D$31,"Sí") -> 26 | C11: =COUNTIF(Calendario!$D$2:$D$31,"Sí") -> 26
A12: Colchón (días) | B12: =B11-B10 -> 2 | C12: =C11-C10 -> 2
A13: Ocupación | B13: =B10/B11 -> 0.92307692 | C13: =C10/C11 -> 0.92307692
A15: Además del colchón hay 4 domingos libres. Los huecos concretos: B en D8–D9, A en D22 y D25.

Sheet Calendario
A1: Día | B1: Fecha | C1: Día semana | D1: Laborable
A2: 1 | B2: =Supuestos!B4 -> 46323 | C2: =CHOOSE(WEEKDAY(B2,2),"lun","mar","mié","jue","vie","sáb","dom") -> mié | D2: =IF(WEEKDAY(B2,2)=7,"No","Sí") -> Sí
A3: 2 | B3: =B2+1 -> 46324 | C3: =CHOOSE(WEEKDAY(B3,2),"lun","mar","mié","jue","vie","sáb","dom") -> jue | D3: =IF(WEEKDAY(B3,2)=7,"No","Sí") -> Sí
A4: 3 | B4: =B3+1 -> 46325 | C4: =CHOOSE(WEEKDAY(B4,2),"lun","mar","mié","jue","vie","sáb","dom") -> vie | D4: =IF(WEEKDAY(B4,2)=7,"No","Sí") -> Sí
A5: 4 | B5: =B4+1 -> 46326 | C5: =CHOOSE(WEEKDAY(B5,2),"lun","mar","mié","jue","vie","sáb","dom") -> sáb | D5: =IF(WEEKDAY(B5,2)=7,"No","Sí") -> Sí
A6: 5 | B6: =B5+1 -> 46327 | C6: =CHOOSE(WEEKDAY(B6,2),"lun","mar","mié","jue","vie","sáb","dom") -> dom | D6: =IF(WEEKDAY(B6,2)=7,"No","Sí") -> No
A7: 6 | B7: =B6+1 -> 46328 | C7: =CHOOSE(WEEKDAY(B7,2),"lun","mar","mié","jue","vie","sáb","dom") -> lun | D7: =IF(WEEKDAY(B7,2)=7,"No","Sí") -> Sí
A8: 7 | B8: =B7+1 -> 46329 | C8: =CHOOSE(WEEKDAY(B8,2),"lun","mar","mié","jue","vie","sáb","dom") -> mar | D8: =IF(WEEKDAY(B8,2)=7,"No","Sí") -> Sí
A9: 8 | B9: =B8+1 -> 46330 | C9: =CHOOSE(WEEKDAY(B9,2),"lun","mar","mié","jue","vie","sáb","dom") -> mié | D9: =IF(WEEKDAY(B9,2)=7,"No","Sí") -> Sí
A10: 9 | B10: =B9+1 -> 46331 | C10: =CHOOSE(WEEKDAY(B10,2),"lun","mar","mié","jue","vie","sáb","dom") -> jue | D10: =IF(WEEKDAY(B10,2)=7,"No","Sí") -> Sí
A11: 10 | B11: =B10+1 -> 46332 | C11: =CHOOSE(WEEKDAY(B11,2),"lun","mar","mié","jue","vie","sáb","dom") -> vie | D11: =IF(WEEKDAY(B11,2)=7,"No","Sí") -> Sí
A12: 11 | B12: =B11+1 -> 46333 | C12: =CHOOSE(WEEKDAY(B12,2),"lun","mar","mié","jue","vie","sáb","dom") -> sáb | D12: =IF(WEEKDAY(B12,2)=7,"No","Sí") -> Sí
A13: 12 | B13: =B12+1 -> 46334 | C13: =CHOOSE(WEEKDAY(B13,2),"lun","mar","mié","jue","vie","sáb","dom") -> dom | D13: =IF(WEEKDAY(B13,2)=7,"No","Sí") -> No
A14: 13 | B14: =B13+1 -> 46335 | C14: =CHOOSE(WEEKDAY(B14,2),"lun","mar","mié","jue","vie","sáb","dom") -> lun | D14: =IF(WEEKDAY(B14,2)=7,"No","Sí") -> Sí
... A31: 30 | B31: =B30+1 -> 46352 | C31: =CHOOSE(WEEKDAY(B31,2),"lun","mar","mié","jue","vie","sáb","dom") -> jue | D31: =IF(WEEKDAY(B31,2)=7,"No","Sí") -> Sí

Sheet Hitos y recortes
A1: Hitos de control
A3: Hito | B3: Día | C3: Fecha | D3: Si falla, recortar (en este orden)
A4: TP0 cerrado | B4: 2 | C4: =INDEX(Calendario!$B$2:$B$31,MATCH(B4,Calendario!$A$2:$A$31,0)) -> 46324 | D4: —
A5: TP1 listo (demo en vivo) | B5: 9 | C5: =INDEX(Calendario!$B$2:$B$31,MATCH(B5,Calendario!$A$2:$A$31,0)) -> 46331 | D5: Dejar HU15 (anulación) solo documentada
A6: TP2 listo + auditoría cruzada | B6: 16 | C6: =INDEX(Calendario!$B$2:$B$31,MATCH(B6,Calendario!$A$2:$A$31,0)) -> 46338 | D6: Permisos individuales editables solo por Admin/API, sin pantalla (−0.5 d)
A7: TP3 flujo integrado | B7: 22 | C7: =INDEX(Calendario!$B$2:$B$31,MATCH(B7,Calendario!$A$2:$A$31,0)) -> 46344 | D7: Reducir eventos Socket.IO a 2: venta.registrada e importacion.lista (−0.5 d)
A8: TP4 listo + congelamiento funcional | B8: 25 | C8: =INDEX(Calendario!$B$2:$B$31,MATCH(B8,Calendario!$A$2:$A$31,0)) -> 46347 | D8: Cobertura concentrada en costeo y caja
A9: TFI: informe PDF + presentación | B9: 30 | C9: =INDEX(Calendario!$B$2:$B$31,MATCH(B9,Calendario!$A$2:$A$31,0)) -> 46352 | D9: —
A11: No recortables (la guía los exige para aprobar): GraphQL (3 queries + 1 mutation), las 3 consultas optimizadas y el flujo de IA completo.
